<mujoco>
  <compiler inertiafromgeom="true" angle="degree" coordinate="local" />
 <visual>
        <map fogstart="3" fogend="5" force="0.1" znear="0.5"/>
        <quality shadowsize="2048" offsamples="8"/>
        <global offwidth="800" offheight="800"/>
    </visual>
  <default>
    <joint limited="false" armature="0" damping="0" />
    <geom condim="3" conaffinity="0" margin="0" friction="1 0.5 0.5" rgba="0.8 0.6 0.4 1" density="100" />
  </default>
  <asset>
    <texture type="skybox" builtin="gradient" width="100" height="100" rgb1="1 1 1" rgb2="0 0 0" />
    <texture name="texgeom" type="cube" builtin="flat" mark="cross" width="127" height="1278" rgb1="0.8 0.6 0.4" rgb2="0.8 0.6 0.4" markrgb="1 1 1" random="0.01" />
    <texture name="texplane" type="2d" builtin="checker" rgb1="0 0 0" rgb2="0.8 0.8 0.8" width="100" height="100" />    <material name='MatPlane' texture="texplane" shininess="1" texrepeat="30 30" specular="1"  reflectance="0.5" />
    <material name='geom' texture="texgeom" texuniform="true" />
  </asset>
  <option timestep="0.02" integrator="RK4" />
  <worldbody>
    <light directional="true" cutoff="100" exponent="1" diffuse="1 1 1" specular=".1 .1 .1" pos="0 0 1.3" dir="-0 0 -1.3" />
    <geom name='floor' material="MatPlane" pos='0 0 0' size='40 40 40' type='plane' conaffinity='1' rgba='0.8 0.9 0.8 1' condim='3' />
    <body name="point" pos="0 0 0">
      <joint type="slide" name="push_1" axis='1 0 0' damping='1'/>
      <joint type="slide" name="push_2" axis='0 1 0' damping='1'/>
      <geom name="arrow1" type="capsule" size="0.2 0.1 0.1" pos="-0.3 -2.4 0.5" rgba="0 0 0 1" />
      <geom name="arrow2" type="capsule" size="0.2 0.1 0.1" pos="0.3 -2.4 0.5" rgba="0 0 0 1"/>
      <geom name="point" type="sphere" size="0.5" pos="0 -2 0.5" density="100" conaffinity='1' contype='1' rgba='0 0 2 3' />
    </body>
    <body name='walls' pos="0 0 0">
       <geom name="rod1" type="box" pos="20 0 0.0" size="1 20 1" density="100"/>
       <geom name="rod2" type="box" pos="-20 0 0.0" size="1 20 1" density="100"/>
       <geom name="rod3" type="box" pos="0 20 0.0" size="20 1 1" density="100"/>
       <geom name="rod4" type="box" pos="0 -20 0.0" size="20 1 1" density="100"/>
    </body>
    <body name='cylinder'>
      <geom name="cylinder" type="cylinder" size="0.5 1 " pos="0.0 2.0 1" density="0.01" conaffinity='1' contype='1' rgba='1 2 3 2' solref="0.02 0.001" />
      <joint name="goal_slidey" type="slide" pos="0 0 0" axis="0 1 0"  damping="0.5"/>
      <joint name="goal_slidex" type="slide" pos="0 0 0" axis="1 0 0"  damping="0.5"/>
</body>

  </worldbody>
  <actuator>
     <motor ctrllimited="true" ctrlrange="-40.0 40.0" joint='push_2' />
     <motor ctrllimited="true" ctrlrange="-40.0 40.0" joint='push_1' />
  </actuator>
</mujoco>
